<robot name="sr-scara">
    <!-- Robot description -->
    <link name="base_link">
        <visual>
            <origin xyz="0.0 0.0 0.0" rpy="0.0 0.0 0.0"/>
            <geometry>
                <mesh filename="package://simple_robots/scara/meshs/base.dae" scale="1.0 1.0 1.0"/>
            </geometry>
        </visual>
        <collision>
            <origin xyz="0.0 0.0 0.0" rpy="0.0 0.0 0.0"/>
            <geometry>
                <box size="0.0 0.0 0.0"/>
            </geometry>
        </collision>
    </link>

    <link name="link1">
        <inertial>
            <origin xyz="0.0 0.0 0.0" rpy="0.0 0.0 0.0"/>
            <mass value="1.0"/>
            <inertia ixx="1.0" ixy="0.0" ixz="0.0" iyy="1.0" iyz="0.0" izz="1.0"/>
        </inertial>
        <visual>
            <origin xyz="0.5 0.0 0.0" rpy="0.0 0.0 0.0"/>
            <geometry>
                <mesh filename="package://simple_robots/scara/meshs/link1.dae" scale="1.0 1.0 1.0"/>
            </geometry>
        </visual>
    </link>

    <link name="link2">
        <inertial>
            <origin xyz="0.0 0.0 0.0" rpy="0.0 0.0 0.0"/>
            <mass value="1.0"/>
            <inertia ixx="1.0" ixy="0.0" ixz="0.0" iyy="1.0" iyz="0.0" izz="1.0"/>
        </inertial>
        <visual>
            <origin xyz="0.5 0.0 0.0" rpy="0.0 0.0 0.0"/>
            <geometry>
                <mesh filename="package://simple_robots/scara/meshs/link2.dae" scale="1.0 1.0 1.0"/>
            </geometry>
        </visual>
    </link>

    <link name="link3">
    </link>

    <link name="link4">
        <inertial>
            <origin xyz="0.0 0.0 0.0" rpy="0.0 0.0 0.0"/>
            <mass value="1.0"/>
            <inertia ixx="1.0" ixy="0.0" ixz="0.0" iyy="1.0" iyz="0.0" izz="1.0"/>
        </inertial>
        <visual>
            <origin xyz="0.0 0.0 0.074" rpy="0.0 0.0 0.0"/>
            <geometry>
                <mesh filename="package://simple_robots/scara/meshs/link3.dae" scale="1.0 1.0 1.0"/>
            </geometry>
        </visual>
    </link>

    <joint name="joint1" type="revolute">
        <origin xyz="0.0 0.0 0.94" rpy="0.0 0.0 0.0"/>
        <parent link="base_link"/>
        <child link="link1"/>
        <axis xyz="0.0 0.0 1.0"/>
        <limit lower="-3.14" upper="3.140" effort="0.0" velocity="0.0"/>
    </joint>

    <joint name="joint2" type="revolute">
        <origin xyz="0.5 0.0 0.0" rpy="0.0 0.0 0.0"/>
        <parent link="link1"/>
        <child link="link2"/>
        <axis xyz="0.0 0.0 1.0"/>
        <limit lower="-1.57" upper="1.57" effort="0.0" velocity="0.0"/>
    </joint>

    <joint name="joint3" type="revolute">
        <origin xyz="0.5 0.0 0.0" rpy="0.0 0.0 0.0"/>
        <parent link="link2"/>
        <child link="link3"/>
        <axis xyz="0.0 0.0 1.0"/>
        <limit lower="-3.14" upper="3.140" effort="0.0" velocity="0.0"/>
    </joint>

    <joint name="joint4" type="prismatic">
        <origin xyz="0.0 0.0 0.0" rpy="3.14 0.0 0.0"/>
        <parent link="link3"/>
        <child link="link4"/>
        <axis xyz="0.0 0.0 1.0"/>
        <limit lower="0" upper="0.716" effort="0.0" velocity="0.0"/>
    </joint>
</robot>